Traceback (most recent call last):
  File "C:\Users\Eliana Gomez\anaconda3\envs\WIND\lib\site-packages\jupyter_cache\executors\utils.py", line 58, in single_nb_execution
    executenb(
  File "C:\Users\Eliana Gomez\anaconda3\envs\WIND\lib\site-packages\nbclient\client.py", line 1305, in execute
    return NotebookClient(nb=nb, resources=resources, km=km, **kwargs).execute()
  File "C:\Users\Eliana Gomez\anaconda3\envs\WIND\lib\site-packages\jupyter_core\utils\__init__.py", line 165, in wrapped
    return loop.run_until_complete(inner)
  File "C:\Users\Eliana Gomez\anaconda3\envs\WIND\lib\asyncio\base_events.py", line 647, in run_until_complete
    return future.result()
  File "C:\Users\Eliana Gomez\anaconda3\envs\WIND\lib\site-packages\nbclient\client.py", line 705, in async_execute
    await self.async_execute_cell(
  File "C:\Users\Eliana Gomez\anaconda3\envs\WIND\lib\site-packages\nbclient\client.py", line 1058, in async_execute_cell
    await self._check_raise_for_error(cell, cell_index, exec_reply)
  File "C:\Users\Eliana Gomez\anaconda3\envs\WIND\lib\site-packages\nbclient\client.py", line 914, in _check_raise_for_error
    raise CellExecutionError.from_cell_and_msg(cell, exec_reply_content)
nbclient.exceptions.CellExecutionError: An error occurred while executing the following cell:
------------------
X_train, X_val, X_test = X_train.reshape((X_train.shape[0], X_train.shape[1], 1)), 
                                        X_val.reshape((X_val.shape[0], X_val.shape[1], 1)), 
                                        X_test.reshape((X_test.shape[0], X_test.shape[1], 1))

print('Shape of 3D arrays:', X_train.shape, X_val.shape, X_test.shape)
------------------


[1;36m  Cell [1;32mIn[24], line 2[1;36m[0m
[1;33m    X_val.reshape((X_val.shape[0], X_val.shape[1], 1)),[0m
[1;37m    ^[0m
[1;31mIndentationError[0m[1;31m:[0m unexpected indent


